Workbook

Sheet Instructions
B2: Transition Barrier Assessment — Working Tool
B3: CLTI Dimension 1: Transition Feasibility — Sector × Region Assessment
B5: What this workbook is
B6: A living research tool for assessing transition feasibility barriers — Technology, Regulation, and Demand & Economics — across 9 hard-to-abate sectors and 3 regions (EU, US, China). It is designed to be updated on an ongoing basis as new evidence is published by the named authoritative sources, and eventually to be partially automated (see the Pipeline Design Document).
B8: How to use it
B9: 1. Criteria Reference | C9: The fixed assessment framework — 35 criteria (mostly 3-4 per sector) across the three constraint categories. Each criterion has a precise metric, a scoring rubric, and named authoritative sources. This sheet should change rarely — only when the criteria themselves are refined.
B10: 2. Assessment Matrix | C10: The working sheet. One row per sector × criterion × region (105 rows). Rating, Confidence, Evidence, and Source columns are editable — shown with a light blue fill and blue font. Update these as research progresses. Rating and Confidence use dropdown validation to keep values consistent.
B11: 3. Dashboard | C11: Automatically computed sector × region summary, built with formulas that reference the Assessment Matrix. It recalculates as you update ratings — no manual maintenance needed.
B12: 4. Sector sheets (Steel, Cement, etc.) | C12: Optional per-sector filtered views for focused research sessions — same data as the Assessment Matrix, pre-filtered to one sector, useful when a researcher is working through a single sector's citations.
B14: Rating scale
B15: ●●● H | C15: High feasibility — Commercial pathway available now, or economics/regulation already supportive at scale
B16: ●●○ M | C16: Moderate feasibility — Pathway exists or is emerging; at least one material constraint unresolved
B17: ●○○ L | C17: Low feasibility — Pathway not commercially available, or a required precondition (infrastructure, price, mandate) is absent
B19: Confidence tiers
B20: confidence: high = directly sourced from a named primary document with a verified URL, checked within the last research cycle; medium = sourced but figure may be >12 months old, from a secondary/aggregator source, or triangulated from multiple partial sources; low = directional estimate pending primary source verification (typically because the primary source is not in English, is subscription-gated, or requires company-specific retrieval not yet performed).
B22: Assessment basis and important caveat
B23: Desk research synthesis by the CLTI research team. Sources were verified directly against primary publishers (EUR-Lex for all EU legislation, official agency sites for US/China regulatory sources, and named institutional report pages for IEA/IRENA/USGS/World Bank/NGFS/IPCC data) across two verification passes, with 88 of 95 source entries across the 35-criteria schema carrying a precise, checked URL or document locator. The remaining 7 are company-disclosure sources, correctly flagged with a retrieval methodology rather than a single URL, since the relevant company varies by which entity is being assessed. Seven ratings were revised during the first verification pass to reflect material 2025 policy developments not captured in the original baseline — most significantly the One Big Beautiful Bill Act's acceleration of Section 45V and termination of Section 30D, and the Congressional Review Act repeal of the EPA methane fee. A second pass added five further institutional sources (Energy Transitions Commission, NGFS Scenario Explorer, LSE Grantham's Climate Change Laws of the World, IPCC AR6 WG3, and McKinsey green premium research) that strengthen the evidentiary base for carbon-price thresholds, technology pathways, and weak single-country government sources. Figures should still be treated as a snapshot: even verified sources move, and each rating's 'Last Verified' date in the Assessment Matrix is the field to check before using a figure in a client-facing output.
B25: Last updated: 2026-08-14

Sheet Criteria Reference
A1: CLTI Dimension 1 — Criteria Reference (35 criteria across 9 sectors) | J1: 88 of 95 sources carry a verified, clickable locator — see the Sources sheet for the full registry.
A2: Sector | B2: Category | C2: Code | D2: Criterion | E2: Metric Definition | F2: Unit | G2: Rubric — High | H2: Rubric — Moderate | I2: Rubric — Low | J2: Primary Sources | K2: Source Links
A3: Power & Utilities | B3: Technology | C3: PWR-T1 | D3: Levelised cost of renewable generation vs. new-build fossil | E3: LCOE of utility-scale solar PV and onshore wind (USD/MWh) vs. LCOE of new-build CCGT/coal in the same region | F3: USD/MWh, ratio | G3: Renewable LCOE at or below new-build fossil LCOE without subsidy | H3: Renewable LCOE within 10-30% of new-build fossil LCOE, or below only with subsidy | I3: Renewable LCOE more than 30% above new-build fossil LCOE | J3: IEA World Energy Investment (International Energy Agency); IRENA Renewable Power Generation Costs (International Renewable Energy Agency); Lazard Levelized Cost of Energy Analysis (Lazard) | K3: https://www.iea.org/reports/world-energy-investment-2025 https://www.irena.org/Publications/2024/Sep/Renewable-Power-Generation-Costs-in-2023 https://www.lazard.com/research-insights/levelized-cost-of-energyplus/
A4: Power & Utilities | B4: Technology | C4: PWR-T2 | D4: Grid-scale storage / firming technology readiness | E4: Deployed grid-scale battery storage capacity (GWh) relative to variable renewable capacity (GW) in the region; TRL of long-duration storage | F4: GWh storage per GW variable renewables | G4: Storage-to-renewables ratio and grid flexibility sufficient to avoid material curtailment (region-specific benchmark, informed by IEA grid integration studies) | H4: Storage deployment underway but curtailment or grid congestion already material | I4: Storage capacity negligible relative to variable renewable penetration | J4: IEA Energy Storage (International Energy Agency); BloombergNEF Energy Storage Outlook (BloombergNEF) | K4: https://www.iea.org/energy-system/electricity/grid-scale-storage https://about.bnef.com/
A5: Power & Utilities | B5: Regulation | C5: PWR-R1 | D5: Effective carbon price on power generation | E5: Carbon price applicable to power sector emissions (ETS price, carbon tax, or implicit price via clean energy mandate penalty) | F5: USD/tCO2 | G5: Effective carbon price exceeds USD 60/tCO2 or binding 100% clean generation mandate with penalty | H5: Effective carbon price USD 15-60/tCO2, or clean generation target without binding penalty | I5: No material carbon price or clean generation mandate | J5: EU ETS carbon price (European Energy Exchange (EEX) / European Commission); World Bank Carbon Pricing Dashboard (World Bank Group); China national ETS price (Shanghai Environment and Energy Exchange); NGFS Climate Scenarios (Network for Greening the Financial System (127 central banks and supervisors), hosted by IIASA) | K5: https://www.eex.com/en/market-data/environmental-markets/spot-market https://carbonpricingdashboard.worldbank.org/ https://www.cneeex.com/ https://www.ngfs.net/ngfs-scenarios-portal/data-resources/
A6: Power & Utilities | B6: Regulation | C6: PWR-R2 | D6: Renewable deployment target and permitting regime | E6: Legally binding renewable capacity target (GW or % of generation) by target year; average grid connection queue time (years) | F6: GW target, years to connect | G6: Legally binding target with permitting reform reducing connection queue below 3 years | H6: Target exists (binding or aspirational) but connection queue exceeds 3 years | I6: No binding target, or connection queue exceeds 7 years | J6: EU REPowerEU / Fit for 55 targets (European Commission); IEA Renewables market report (International Energy Agency); China NEA renewable targets (National Energy Administration (China)) | K6: https://eur-lex.europa.eu/eli/dir/2018/2001/oj https://www.iea.org/reports/renewables-2024 https://www.nea.gov.cn/
A7: Power & Utilities | B7: Demand & Economics | C7: PWR-D1 | D7: Corporate and utility PPA market depth | E7: Annual volume of signed corporate/utility power purchase agreements (GW) for renewable generation in the region | F7: GW/year signed | G7: PPA market established and growing; multi-year forward contracting standard practice | H7: PPA market exists but thin or concentrated in few counterparties | I7: PPA market negligible; renewable generation sold predominantly on spot/merchant basis | J7: BloombergNEF Corporate Energy Market Outlook (BloombergNEF); RE100 Annual Report (Climate Group / CDP) | K7: https://about.bnef.com/ https://www.there100.org/re100-progress-and-insights-annual-report
A8: Steel | B8: Technology | C8: STL-T1 | D8: Green hydrogen cost vs. DRI-H2 breakeven | E8: Delivered cost of green hydrogen (USD/kg) at production site, vs. estimated breakeven cost for DRI-H2 route to be cost-competitive with BF-BOF at prevailing carbon price | F8: USD/kg H2 | G8: Green hydrogen cost at or below breakeven (typically cited ~USD 1.5-2.0/kg range, region-specific) | H8: Green hydrogen cost within 2x of breakeven | I8: Green hydrogen cost more than 2x breakeven, or no green hydrogen supply chain present | J8: IEA Global Hydrogen Review (International Energy Agency); Mission Possible Partnership Steel Transition Strategy (Mission Possible Partnership / Energy Transitions Commission); BloombergNEF Hydrogen Levelized Cost Report (BloombergNEF); Mission Possible: Reaching Net-Zero Carbon Emissions from Harder-to-Abate Sectors (Energy Transitions Commission (ETC)) | K8: https://www.iea.org/reports/global-hydrogen-review-2024 https://missionpossiblepartnership.org/publications/ https://about.bnef.com/ https://www.energy-transitions.org/publications/mission-possible/
A9: Steel | B9: Technology | C9: STL-T2 | D9: Scrap steel availability (EAF route feasibility) | E9: Domestic scrap steel collection and availability as % of crude steel production capacity | F9: % of production | G9: Scrap availability exceeds 50% of production capacity, supporting EAF as viable low-carbon route without new technology | H9: Scrap availability 25-50% of production capacity | I9: Scrap availability below 25% of production capacity | J9: World Steel Association Steel Statistical Yearbook (World Steel Association (worldsteel)); OECD Steel Market Developments (OECD Steel Committee) | K9: https://worldsteel.org/data/world-steel-in-figures/ https://www.oecd.org/en/topics/sub-issues/steel-market-developments.html
A10: Steel | B10: Regulation | C10: STL-R1 | D10: Effective carbon price on steel production incl. border adjustment | E10: ETS/carbon tax price applicable to steel production, adjusted for free allocation phase-out and any import border levy (e.g. CBAM) | F10: USD/tCO2 net of free allocation | G10: Effective carbon price (net of free allocation) exceeds USD 50/tCO2 with border levy protecting domestic producers from unpriced imports | H10: Carbon price applies but free allocation still material, or no border levy protecting against unpriced competition | I10: No material carbon price on steel production | J10: EU CBAM Regulation (2023/956) and implementing acts (European Commission / Official Journal of the EU); EU ETS free allocation benchmarks - steel (European Commission DG CLIMA); China national ETS sector coverage roadmap (Ministry of Ecology and Environment (China)); NGFS Climate Scenarios (Network for Greening the Financial System (127 central banks and supervisors), hosted by IIASA) | K10: https://eur-lex.europa.eu/eli/reg/2023/956/oj/eng https://eur-lex.europa.eu/eli/reg_impl/2021/447/2026-03-18/eng https://www.mee.gov.cn/ https://www.ngfs.net/ngfs-scenarios-portal/data-resources/
A11: Steel | B11: Regulation | C11: STL-R2 | D11: Green/low-carbon steel public procurement or building-code mandate | E11: Existence and scope of government mandate requiring low-carbon steel in public infrastructure procurement or building codes | F11: Binary/scope descriptor | G11: Binding mandate in force covering material share of public procurement or construction | H11: Voluntary standard or pilot mandate exists | I11: No mandate or standard exists | J11: EU Green Public Procurement criteria - construction (European Commission DG ENV); US Federal Buy Clean Initiative (US General Services Administration / EPA); National/state building codes register (Various national standards bodies) | K11: https://green-business.ec.europa.eu/green-public-procurement_en https://www.sustainability.gov/buyclean/ https://www.iccsafe.org/
A12: Steel | B12: Demand & Economics | C12: STL-D1 | D12: Green steel price premium and recoverability | E12: Market premium for certified low-carbon steel (USD/tonne) vs. conventional, and share of premium covered by signed offtake contracts | F12: USD/tonne premium; % under contract | G12: Documented offtake contracts (e.g. automotive OEM commitments) cover a material share of announced low-carbon capacity at a disclosed premium | H12: Premium exists and some pilot offtake agreements signed, but limited volume | I12: No documented premium recovery mechanism; no material offtake contracts identified | J12: BloombergNEF Green Steel Tracker / Premium report (BloombergNEF); Company investor disclosures (Individual steelmakers (annual reports, capital markets days)); Mission Possible Partnership Steel sector tracker (Mission Possible Partnership) | K12: https://about.bnef.com/ https://missionpossiblepartnership.org/publications/
A13: Cement | B13: Technology | C13: CEM-T1 | D13: CCS capture technology deployment status | E13: Number and capacity (Mtpa CO2) of operational or under-construction full-scale cement CCS facilities in the region | F13: Mtpa capacity, facility count | G13: At least one full-scale (>0.3 Mtpa) operational facility in the region with a track record | H13: Facility under construction or in final investment decision (FID) stage | I13: No full-scale facility operational, under construction, or FID-approved in the region | J13: Global CCS Institute CO2RE database (Global CCS Institute); IEA CCUS Projects Database (International Energy Agency); Mission Possible: Reaching Net-Zero Carbon Emissions from Harder-to-Abate Sectors (Energy Transitions Commission (ETC)) | K13: https://co2re.co/FacilityData https://co2re.co/FacilityData https://www.energy-transitions.org/publications/mission-possible/
... A37: Oil & Gas Upstream | B37: Demand & Economics | C37: OGU-D1 | D37: Market demand trajectory / structural decline exposure | E37: Projected regional oil and gas demand trajectory to 2035 under stated policy vs. announced pledges scenarios (IEA) | F37: % change in demand 2024-2035 | G37: Demand trajectory stable or growing under stated policies (lower stranding risk near-term, i.e. more 'feasible' to continue operating economically) | H37: Demand trajectory flat to moderate decline | I37: Demand trajectory in structural decline under regional policy settings | J37: IEA World Energy Outlook - regional demand scenarios (International Energy Agency) | K37: https://www.iea.org/reports/world-energy-outlook-2024

Sheet Sources
A1: Source Registry — 86 distinct sources across all 35 criteria | E1: Verified 2026-08-14. See source_registry.json for the complete machine-readable version.
A2: Source Name | B2: Publisher | C2: Used By (Criteria Codes) | D2: Access Pattern | E2: Refresh Cadence | F2: Locator / What To Check | G2: Link
A3: Company disclosures | B3: Airlines and SAF producers | C3: AVI-D1 | D3: Company Disclosure | E3: per company reporting cycle (typically annual, some quarterly) | F3: No single URL — retrieve from the specific company's investor relations page (annual report, capital markets day materials, or sustainability report). Identify relevant companies via sector leaders named in Mission Possible Partnership / BloombergNEF sector trackers, then search each company's IR site directly. This is the source type flagged in the Automation Pipeline Design Document (Section 5.6) as requiring discovery-and-triage rather than single-URL retrieval. | G3: See locator note
A4: BloombergNEF Energy Storage Outlook | B4: BloombergNEF | C4: PWR-T2 | D4: Periodic PDF Report | E4: varies by report series, generally annual | F4: Subscription service; specific report titles vary by year — verify current title via BNEF's published research index at each review cycle | G4: https://about.bnef.com/
A5: BloombergNEF Corporate Energy Market Outlook | B5: BloombergNEF | C5: PWR-D1 | D5: Periodic PDF Report | E5: varies by report series, generally annual | F5: Subscription service; specific report titles vary by year — verify current title via BNEF's published research index at each review cycle | G5: https://about.bnef.com/
A6: BloombergNEF Hydrogen Levelized Cost Report | B6: BloombergNEF | C6: STL-T1 | D6: Periodic PDF Report | E6: varies by report series, generally annual | F6: Subscription service; specific report titles vary by year — verify current title via BNEF's published research index at each review cycle | G6: https://about.bnef.com/
A7: BloombergNEF Green Steel Tracker / Premium report | B7: BloombergNEF | C7: STL-D1 | D7: Periodic PDF Report | E7: varies by report series, generally annual | F7: Subscription service; specific report titles vary by year — verify current title via BNEF's published research index at each review cycle | G7: https://about.bnef.com/
A8: California Advanced Clean Fleets / Advanced Clean Trucks regulation | B8: California Air Resources Board | C8: HDT-R1 | D8: Government Publication | E8: monitor closely given ongoing litigation/waiver status | F8: ZEV sales percentage requirements and fleet purchase mandates by year | G8: https://ww2.arb.ca.gov/our-work/programs/advanced-clean-fleets
A9: China charging infrastructure statistics | B9: China Electric Vehicle Charging Infrastructure Promotion Alliance | C9: HDT-D1 | D9: Industry Tracker | E9: monthly, publisher updates | F9: Monthly public charging infrastructure statistics | G9: http://www.evcipa.org.cn/
A10: Clarksons Research World Fleet Register | B10: Clarksons Research | C10: SHP_T1 | D10: Industry Tracker | E10: continuous (subscription required for full access) | F10: Subscription database; new-build order book filterable by fuel type and propulsion | G10: https://www.clarksons.net/wfr/
A11: RE100 Annual Report | B11: Climate Group / CDP | C11: PWR-D1 | D11: Periodic PDF Report | E11: annual | F11: Annual report on corporate renewable procurement volumes by RE100 member companies | G11: https://www.there100.org/re100-progress-and-insights-annual-report
A12: DNV Alternative Fuels Insight platform | B12: DNV | C12: SHP_T1 | D12: Industry Tracker | E12: continuously updated by publisher | F12: Free public dashboard tracking alternative-fuel vessel orders and bunkering infrastructure by fuel type | G12: https://afi.dnv.com/
A13: Mission Possible: Reaching Net-Zero Carbon Emissions from Harder-to-Abate Sectors | B13: Energy Transitions Commission (ETC) | C13: AVI-T1, CEM-T1, CHM-T1, SHP_T1, STL-T1 | D13: Periodic PDF Report | E13: irregular — ETC publishes updates and sector-specific follow-ons rather than a fixed annual cycle; check publications page each review | F13: Sector-specific technical abatement pathways for cement, steel, plastics, aviation, shipping, trucking; distinguishes proven-technology sectors from those needing further technology investment | G13: https://www.energy-transitions.org/publications/mission-possible/
... A88: Company disclosures | B88: e.g. Maersk, cargo owner coalitions (coZEV) | C88: SHP_D1 | D88: Company Disclosure | E88: per company reporting cycle (typically annual, some quarterly) | F88: No single URL — retrieve from the specific company's investor relations page (annual report, capital markets day materials, or sustainability report). Identify relevant companies via sector leaders named in Mission Possible Partnership / BloombergNEF sector trackers, then search each company's IR site directly. This is the source type flagged in the Automation Pipeline Design Document (Section 5.6) as requiring discovery-and-triage rather than single-URL retrieval. | G88: See locator note

Sheet Assessment Matrix
A1: CLTI Dimension 1 — Assessment Matrix (105 rows = 35 criteria × 3 regions) | H1: Blue text = editable fields. Rating/Confidence use dropdown validation.
A2: Sector | B2: Category | C2: Code | D2: Criterion | E2: Region | F2: Rating | G2: Confidence | H2: Evidence / Basis for Rating | I2: Source(s) | J2: Last Verified
A3: Power & Utilities | B3: Technology | C3: PWR-T1 | D3: Levelised cost of renewable generation vs. new-build fossil | E3: European Union | F3: H | G3: high | H3: EU utility-scale solar and onshore wind LCOE (~EUR 40-60/MWh in strong-resource markets) is at or below new-build CCGT LCOE; renewables have won the large majority of new capacity tenders since 2022 | I3: IEA World Energy Investment 2023; IRENA Renewable Power Generation Costs 2023 | J3: 2026-08-14
A4: Power & Utilities | B4: Technology | C4: PWR-T1 | D4: Levelised cost of renewable generation vs. new-build fossil | E4: United States | F4: H | G4: high | H4: Unsubsidized utility-scale solar and wind LCOE in Lazard's most recent analysis sits below new-build gas CCGT in most regions; IRA production tax credits further widen the gap | I4: Lazard Levelized Cost of Energy Analysis; IEA World Energy Investment 2023 | J4: 2026-08-14
A5: Power & Utilities | B5: Technology | C5: PWR-T1 | D5: Levelised cost of renewable generation vs. new-build fossil | E5: China | F5: H | G5: medium | H5: China's solar and wind LCOE benefits from the world's largest manufacturing scale; renewables are cost-competitive with new coal in the large majority of provinces | I5: IEA World Energy Investment 2023; IRENA Renewable Power Generation Costs 2023 | J5: 2026-08-14
A6: Power & Utilities | B6: Technology | C6: PWR-T2 | D6: Grid-scale storage / firming technology readiness | E6: European Union | F6: M | G6: medium | H6: Grid-scale battery deployment growing rapidly but curtailment already material in high-renewable-penetration markets (e.g. Germany, Spain, Italy) pending grid reinforcement | I6: IEA Energy Storage tracking report; ENTSO-E curtailment statistics | J6: 2026-08-14
A7: Power & Utilities | B7: Technology | C7: PWR-T2 | D7: Grid-scale storage / firming technology readiness | E7: United States | F7: M | G7: medium | H7: Battery storage additions record-high but concentrated in a few states (California, Texas); interconnection queue backlogs remain a binding constraint nationally | I7: IEA Energy Storage tracking report; BloombergNEF Energy Storage Outlook | J7: 2026-08-14
A8: Power & Utilities | B8: Technology | C8: PWR-T2 | D8: Grid-scale storage / firming technology readiness | E8: China | F8: M | G8: medium | H8: China leads global battery storage manufacturing and deployment volume, but curtailment of wind/solar in resource-rich western provinces remains a persistent grid integration issue | I8: IEA Energy Storage tracking report | J8: 2026-08-14
A9: Power & Utilities | B9: Regulation | C9: PWR-R1 | D9: Effective carbon price on power generation | E9: European Union | F9: H | G9: high | H9: EU ETS price has traded consistently in the EUR 60-90/tCO2 range through 2024-2026, exceeding the H threshold | I9: EEX EUA spot price series; European Commission EU ETS reporting | J9: 2026-08-14
A10: Power & Utilities | B10: Regulation | C10: PWR-R1 | D10: Effective carbon price on power generation | E10: United States | F10: M | G10: high | H10: No federal carbon price; state-level programmes (California cap-and-trade, RGGI) apply a moderate price only in participating states, well below the EU level | I10: World Bank Carbon Pricing Dashboard | J10: 2026-08-14
A11: Power & Utilities | B11: Regulation | C11: PWR-R1 | D11: Effective carbon price on power generation | E11: China | F11: M | G11: high | H11: China national ETS covers power generation with a 2024 composite closing price ranging CNY 69-106/tonne (year-end CNY 97.49/t, approx. USD 13-14/t), rising further to CNY 66.9-97/t through the 2025 sectoral expansion period — consistently below the USD 60/tCO2 H threshold and well below the EU ETS level (EUR 70-90/t). | I11: Progress Report of China's National Carbon Market (2025), Ministry of Ecology and Environment via Henan provincial exchange; ICAP China National ETS tracker | J11: 2026-08-14
A12: Power & Utilities | B12: Regulation | C12: PWR-R2 | D12: Renewable deployment target and permitting regime | E12: European Union | F12: H | G12: high | H12: Binding 2030 renewables target under the revised Renewable Energy Directive, combined with permitting reform under REPowerEU aimed at reducing approval timelines | I12: European Commission REPowerEU / Renewable Energy Directive (EU) 2023/2413 | J12: 2026-08-14
A13: Power & Utilities | B13: Regulation | C13: PWR-R2 | D13: Renewable deployment target and permitting regime | E13: United States | F13: M | G13: high | H13: No binding federal renewable target; state-level RPS programmes vary widely; interconnection queue times remain a widely documented bottleneck exceeding 3 years in most regions | I13: IEA Renewables market report; Lawrence Berkeley National Laboratory interconnection queue studies | J13: 2026-08-14
... A107: Oil & Gas Upstream | B107: Demand & Economics | C107: OGU-D1 | D107: Market demand trajectory / structural decline exposure | E107: China | F107: M | G107: medium | H107: Chinese gas demand continues to grow as a coal-substitution fuel even as oil demand growth slows, giving a mixed but not sharply declining near-term trajectory under stated policies | I107: IEA World Energy Outlook regional demand scenarios | J107: 2026-08-14

Sheet Dashboard
B2: Sector × Region Feasibility Dashboard
B3: Computed from the Assessment Matrix — average numeric score per sector/region (H=3, M=2, L=1)
B5: Sector | C5: European Union | D5: United States | E5: China
B6: Power & Utilities | C6: =IFERROR((SUMPRODUCT(('Assessment Matrix'!$A$3:$A$107="Power & Utilities")*('Assessment Matrix'!$E$3:$E$107="European Union")*('Assessment Matrix'!$F$3:$F$107="H"))*3+SUMPRODUCT(('Assessment Matrix'!$A$3:$A$107="Power & Utilities")*('Assessment Matrix'!$E$3:$E$107="European Union")*('Assessment Matrix'!$F$3:$F$107="M"))*2+SUMPRODUCT(('Assessment Matrix'!$A$3:$A$107="Power & Utilities")*('Assessment Matrix'!$E$3:$E$107="European Union")*('Assessment Matrix'!$F$3:$F$107="L"))*1)/(SUMPRODUCT(('Assessment Matrix'!$A$3:$A$107="Power & Utilities")*('Assessment Matrix'!$E$3:$E$107="European Union")*(('Assessment Matrix'!$F$3:$F$107="H")+('Assessment Matrix'!$F$3:$F$107="M")+('Assessment Matrix'!$F$3:$F$107="L")))),"") -> 2.8 | D6: =IFERROR((SUMPRODUCT(('Assessment Matrix'!$A$3:$A$107="Power & Utilities")*('Assessment Matrix'!$E$3:$E$107="United States")*('Assessment Matrix'!$F$3:$F$107="H"))*3+SUMPRODUCT(('Assessment Matrix'!$A$3:$A$107="Power & Utilities")*('Assessment Matrix'!$E$3:$E$107="United States")*('Assessment Matrix'!$F$3:$F$107="M"))*2+SUMPRODUCT(('Assessment Matrix'!$A$3:$A$107="Power & Utilities")*('Assessment Matrix'!$E$3:$E$107="United States")*('Assessment Matrix'!$F$3:$F$107="L"))*1)/(SUMPRODUCT(('Assessment Matrix'!$A$3:$A$107="Power & Utilities")*('Assessment Matrix'!$E$3:$E$107="United States")*(('Assessment Matrix'!$F$3:$F$107="H")+('Assessment Matrix'!$F$3:$F$107="M")+('Assessment Matrix'!$F$3:$F$107="L")))),"") -> 2.4 | E6: =IFERROR((SUMPRODUCT(('Assessment Matrix'!$A$3:$A$107="Power & Utilities")*('Assessment Matrix'!$E$3:$E$107="China")*('Assessment Matrix'!$F$3:$F$107="H"))*3+SUMPRODUCT(('Assessment Matrix'!$A$3:$A$107="Power & Utilities")*('Assessment Matrix'!$E$3:$E$107="China")*('Assessment Matrix'!$F$3:$F$107="M"))*2+SUMPRODUCT(('Assessment Matrix'!$A$3:$A$107="Power & Utilities")*('Assessment Matrix'!$E$3:$E$107="China")*('Assessment Matrix'!$F$3:$F$107="L"))*1)/(SUMPRODUCT(('Assessment Matrix'!$A$3:$A$107="Power & Utilities")*('Assessment Matrix'!$E$3:$E$107="China")*(('Assessment Matrix'!$F$3:$F$107="H")+('Assessment Matrix'!$F$3:$F$107="M")+('Assessment Matrix'!$F$3:$F$107="L")))),"") -> 2.4
B7: Steel | C7: =IFERROR((SUMPRODUCT(('Assessment Matrix'!$A$3:$A$107="Steel")*('Assessment Matrix'!$E$3:$E$107="European Union")*('Assessment Matrix'!$F$3:$F$107="H"))*3+SUMPRODUCT(('Assessment Matrix'!$A$3:$A$107="Steel")*('Assessment Matrix'!$E$3:$E$107="European Union")*('Assessment Matrix'!$F$3:$F$107="M"))*2+SUMPRODUCT(('Assessment Matrix'!$A$3:$A$107="Steel")*('Assessment Matrix'!$E$3:$E$107="European Union")*('Assessment Matrix'!$F$3:$F$107="L"))*1)/(SUMPRODUCT(('Assessment Matrix'!$A$3:$A$107="Steel")*('Assessment Matrix'!$E$3:$E$107="European Union")*(('Assessment Matrix'!$F$3:$F$107="H")+('Assessment Matrix'!$F$3:$F$107="M")+('Assessment Matrix'!$F$3:$F$107="L")))),"") -> 2.4 | D7: =IFERROR((SUMPRODUCT(('Assessment Matrix'!$A$3:$A$107="Steel")*('Assessment Matrix'!$E$3:$E$107="United States")*('Assessment Matrix'!$F$3:$F$107="H"))*3+SUMPRODUCT(('Assessment Matrix'!$A$3:$A$107="Steel")*('Assessment Matrix'!$E$3:$E$107="United States")*('Assessment Matrix'!$F$3:$F$107="M"))*2+SUMPRODUCT(('Assessment Matrix'!$A$3:$A$107="Steel")*('Assessment Matrix'!$E$3:$E$107="United States")*('Assessment Matrix'!$F$3:$F$107="L"))*1)/(SUMPRODUCT(('Assessment Matrix'!$A$3:$A$107="Steel")*('Assessment Matrix'!$E$3:$E$107="United States")*(('Assessment Matrix'!$F$3:$F$107="H")+('Assessment Matrix'!$F$3:$F$107="M")+('Assessment Matrix'!$F$3:$F$107="L")))),"") -> 2 | E7: =IFERROR((SUMPRODUCT(('Assessment Matrix'!$A$3:$A$107="Steel")*('Assessment Matrix'!$E$3:$E$107="China")*('Assessment Matrix'!$F$3:$F$107="H"))*3+SUMPRODUCT(('Assessment Matrix'!$A$3:$A$107="Steel")*('Assessment Matrix'!$E$3:$E$107="China")*('Assessment Matrix'!$F$3:$F$107="M"))*2+SUMPRODUCT(('Assessment Matrix'!$A$3:$A$107="Steel")*('Assessment Matrix'!$E$3:$E$107="China")*('Assessment Matrix'!$F$3:$F$107="L"))*1)/(SUMPRODUCT(('Assessment Matrix'!$A$3:$A$107="Steel")*('Assessment Matrix'!$E$3:$E$107="China")*(('Assessment Matrix'!$F$3:$F$107="H")+('Assessment Matrix'!$F$3:$F$107="M")+('Assessment Matrix'!$F$3:$F$107="L")))),"") -> 1
B8: Cement | C8: =IFERROR((SUMPRODUCT(('Assessment Matrix'!$A$3:$A$107="Cement")*('Assessment Matrix'!$E$3:$E$107="European Union")*('Assessment Matrix'!$F$3:$F$107="H"))*3+SUMPRODUCT(('Assessment Matrix'!$A$3:$A$107="Cement")*('Assessment Matrix'!$E$3:$E$107="European Union")*('Assessment Matrix'!$F$3:$F$107="M"))*2+SUMPRODUCT(('Assessment Matrix'!$A$3:$A$107="Cement")*('Assessment Matrix'!$E$3:$E$107="European Union")*('Assessment Matrix'!$F$3:$F$107="L"))*1)/(SUMPRODUCT(('Assessment Matrix'!$A$3:$A$107="Cement")*('Assessment Matrix'!$E$3:$E$107="European Union")*(('Assessment Matrix'!$F$3:$F$107="H")+('Assessment Matrix'!$F$3:$F$107="M")+('Assessment Matrix'!$F$3:$F$107="L")))),"") -> 2.6 | D8: =IFERROR((SUMPRODUCT(('Assessment Matrix'!$A$3:$A$107="Cement")*('Assessment Matrix'!$E$3:$E$107="United States")*('Assessment Matrix'!$F$3:$F$107="H"))*3+SUMPRODUCT(('Assessment Matrix'!$A$3:$A$107="Cement")*('Assessment Matrix'!$E$3:$E$107="United States")*('Assessment Matrix'!$F$3:$F$107="M"))*2+SUMPRODUCT(('Assessment Matrix'!$A$3:$A$107="Cement")*('Assessment Matrix'!$E$3:$E$107="United States")*('Assessment Matrix'!$F$3:$F$107="L"))*1)/(SUMPRODUCT(('Assessment Matrix'!$A$3:$A$107="Cement")*('Assessment Matrix'!$E$3:$E$107="United States")*(('Assessment Matrix'!$F$3:$F$107="H")+('Assessment Matrix'!$F$3:$F$107="M")+('Assessment Matrix'!$F$3:$F$107="L")))),"") -> 1.8 | E8: =IFERROR((SUMPRODUCT(('Assessment Matrix'!$A$3:$A$107="Cement")*('Assessment Matrix'!$E$3:$E$107="China")*('Assessment Matrix'!$F$3:$F$107="H"))*3+SUMPRODUCT(('Assessment Matrix'!$A$3:$A$107="Cement")*('Assessment Matrix'!$E$3:$E$107="China")*('Assessment Matrix'!$F$3:$F$107="M"))*2+SUMPRODUCT(('Assessment Matrix'!$A$3:$A$107="Cement")*('Assessment Matrix'!$E$3:$E$107="China")*('Assessment Matrix'!$F$3:$F$107="L"))*1)/(SUMPRODUCT(('Assessment Matrix'!$A$3:$A$107="Cement")*('Assessment Matrix'!$E$3:$E$107="China")*(('Assessment Matrix'!$F$3:$F$107="H")+('Assessment Matrix'!$F$3:$F$107="M")+('Assessment Matrix'!$F$3:$F$107="L")))),"") -> 1.2
B9: Chemicals | C9: =IFERROR((SUMPRODUCT(('Assessment Matrix'!$A$3:$A$107="Chemicals")*('Assessment Matrix'!$E$3:$E$107="European Union")*('Assessment Matrix'!$F$3:$F$107="H"))*3+SUMPRODUCT(('Assessment Matrix'!$A$3:$A$107="Chemicals")*('Assessment Matrix'!$E$3:$E$107="European Union")*('Assessment Matrix'!$F$3:$F$107="M"))*2+SUMPRODUCT(('Assessment Matrix'!$A$3:$A$107="Chemicals")*('Assessment Matrix'!$E$3:$E$107="European Union")*('Assessment Matrix'!$F$3:$F$107="L"))*1)/(SUMPRODUCT(('Assessment Matrix'!$A$3:$A$107="Chemicals")*('Assessment Matrix'!$E$3:$E$107="European Union")*(('Assessment Matrix'!$F$3:$F$107="H")+('Assessment Matrix'!$F$3:$F$107="M")+('Assessment Matrix'!$F$3:$F$107="L")))),"") -> 2 | D9: =IFERROR((SUMPRODUCT(('Assessment Matrix'!$A$3:$A$107="Chemicals")*('Assessment Matrix'!$E$3:$E$107="United States")*('Assessment Matrix'!$F$3:$F$107="H"))*3+SUMPRODUCT(('Assessment Matrix'!$A$3:$A$107="Chemicals")*('Assessment Matrix'!$E$3:$E$107="United States")*('Assessment Matrix'!$F$3:$F$107="M"))*2+SUMPRODUCT(('Assessment Matrix'!$A$3:$A$107="Chemicals")*('Assessment Matrix'!$E$3:$E$107="United States")*('Assessment Matrix'!$F$3:$F$107="L"))*1)/(SUMPRODUCT(('Assessment Matrix'!$A$3:$A$107="Chemicals")*('Assessment Matrix'!$E$3:$E$107="United States")*(('Assessment Matrix'!$F$3:$F$107="H")+('Assessment Matrix'!$F$3:$F$107="M")+('Assessment Matrix'!$F$3:$F$107="L")))),"") -> 1.25 | E9: =IFERROR((SUMPRODUCT(('Assessment Matrix'!$A$3:$A$107="Chemicals")*('Assessment Matrix'!$E$3:$E$107="China")*('Assessment Matrix'!$F$3:$F$107="H"))*3+SUMPRODUCT(('Assessment Matrix'!$A$3:$A$107="Chemicals")*('Assessment Matrix'!$E$3:$E$107="China")*('Assessment Matrix'!$F$3:$F$107="M"))*2+SUMPRODUCT(('Assessment Matrix'!$A$3:$A$107="Chemicals")*('Assessment Matrix'!$E$3:$E$107="China")*('Assessment Matrix'!$F$3:$F$107="L"))*1)/(SUMPRODUCT(('Assessment Matrix'!$A$3:$A$107="Chemicals")*('Assessment Matrix'!$E$3:$E$107="China")*(('Assessment Matrix'!$F$3:$F$107="H")+('Assessment Matrix'!$F$3:$F$107="M")+('Assessment Matrix'!$F$3:$F$107="L")))),"") -> 1
B10: Critical Minerals & Mining | C10: =IFERROR((SUMPRODUCT(('Assessment Matrix'!$A$3:$A$107="Critical Minerals & Mining")*('Assessment Matrix'!$E$3:$E$107="European Union")*('Assessment Matrix'!$F$3:$F$107="H"))*3+SUMPRODUCT(('Assessment Matrix'!$A$3:$A$107="Critical Minerals & Mining")*('Assessment Matrix'!$E$3:$E$107="European Union")*('Assessment Matrix'!$F$3:$F$107="M"))*2+SUMPRODUCT(('Assessment Matrix'!$A$3:$A$107="Critical Minerals & Mining")*('Assessment Matrix'!$E$3:$E$107="European Union")*('Assessment Matrix'!$F$3:$F$107="L"))*1)/(SUMPRODUCT(('Assessment Matrix'!$A$3:$A$107="Critical Minerals & Mining")*('Assessment Matrix'!$E$3:$E$107="European Union")*(('Assessment Matrix'!$F$3:$F$107="H")+('Assessment Matrix'!$F$3:$F$107="M")+('Assessment Matrix'!$F$3:$F$107="L")))),"") -> 2.25 | D10: =IFERROR((SUMPRODUCT(('Assessment Matrix'!$A$3:$A$107="Critical Minerals & Mining")*('Assessment Matrix'!$E$3:$E$107="United States")*('Assessment Matrix'!$F$3:$F$107="H"))*3+SUMPRODUCT(('Assessment Matrix'!$A$3:$A$107="Critical Minerals & Mining")*('Assessment Matrix'!$E$3:$E$107="United States")*('Assessment Matrix'!$F$3:$F$107="M"))*2+SUMPRODUCT(('Assessment Matrix'!$A$3:$A$107="Critical Minerals & Mining")*('Assessment Matrix'!$E$3:$E$107="United States")*('Assessment Matrix'!$F$3:$F$107="L"))*1)/(SUMPRODUCT(('Assessment Matrix'!$A$3:$A$107="Critical Minerals & Mining")*('Assessment Matrix'!$E$3:$E$107="United States")*(('Assessment Matrix'!$F$3:$F$107="H")+('Assessment Matrix'!$F$3:$F$107="M")+('Assessment Matrix'!$F$3:$F$107="L")))),"") -> 2 | E10: =IFERROR((SUMPRODUCT(('Assessment Matrix'!$A$3:$A$107="Critical Minerals & Mining")*('Assessment Matrix'!$E$3:$E$107="China")*('Assessment Matrix'!$F$3:$F$107="H"))*3+SUMPRODUCT(('Assessment Matrix'!$A$3:$A$107="Critical Minerals & Mining")*('Assessment Matrix'!$E$3:$E$107="China")*('Assessment Matrix'!$F$3:$F$107="M"))*2+SUMPRODUCT(('Assessment Matrix'!$A$3:$A$107="Critical Minerals & Mining")*('Assessment Matrix'!$E$3:$E$107="China")*('Assessment Matrix'!$F$3:$F$107="L"))*1)/(SUMPRODUCT(('Assessment Matrix'!$A$3:$A$107="Critical Minerals & Mining")*('Assessment Matrix'!$E$3:$E$107="China")*(('Assessment Matrix'!$F$3:$F$107="H")+('Assessment Matrix'!$F$3:$F$107="M")+('Assessment Matrix'!$F$3:$F$107="L")))),"") -> 2.5
B11: Aviation | C11: =IFERROR((SUMPRODUCT(('Assessment Matrix'!$A$3:$A$107="Aviation")*('Assessment Matrix'!$E$3:$E$107="European Union")*('Assessment Matrix'!$F$3:$F$107="H"))*3+SUMPRODUCT(('Assessment Matrix'!$A$3:$A$107="Aviation")*('Assessment Matrix'!$E$3:$E$107="European Union")*('Assessment Matrix'!$F$3:$F$107="M"))*2+SUMPRODUCT(('Assessment Matrix'!$A$3:$A$107="Aviation")*('Assessment Matrix'!$E$3:$E$107="European Union")*('Assessment Matrix'!$F$3:$F$107="L"))*1)/(SUMPRODUCT(('Assessment Matrix'!$A$3:$A$107="Aviation")*('Assessment Matrix'!$E$3:$E$107="European Union")*(('Assessment Matrix'!$F$3:$F$107="H")+('Assessment Matrix'!$F$3:$F$107="M")+('Assessment Matrix'!$F$3:$F$107="L")))),"") -> 2 | D11: =IFERROR((SUMPRODUCT(('Assessment Matrix'!$A$3:$A$107="Aviation")*('Assessment Matrix'!$E$3:$E$107="United States")*('Assessment Matrix'!$F$3:$F$107="H"))*3+SUMPRODUCT(('Assessment Matrix'!$A$3:$A$107="Aviation")*('Assessment Matrix'!$E$3:$E$107="United States")*('Assessment Matrix'!$F$3:$F$107="M"))*2+SUMPRODUCT(('Assessment Matrix'!$A$3:$A$107="Aviation")*('Assessment Matrix'!$E$3:$E$107="United States")*('Assessment Matrix'!$F$3:$F$107="L"))*1)/(SUMPRODUCT(('Assessment Matrix'!$A$3:$A$107="Aviation")*('Assessment Matrix'!$E$3:$E$107="United States")*(('Assessment Matrix'!$F$3:$F$107="H")+('Assessment Matrix'!$F$3:$F$107="M")+('Assessment Matrix'!$F$3:$F$107="L")))),"") -> 1.6666667 | E11: =IFERROR((SUMPRODUCT(('Assessment Matrix'!$A$3:$A$107="Aviation")*('Assessment Matrix'!$E$3:$E$107="China")*('Assessment Matrix'!$F$3:$F$107="H"))*3+SUMPRODUCT(('Assessment Matrix'!$A$3:$A$107="Aviation")*('Assessment Matrix'!$E$3:$E$107="China")*('Assessment Matrix'!$F$3:$F$107="M"))*2+SUMPRODUCT(('Assessment Matrix'!$A$3:$A$107="Aviation")*('Assessment Matrix'!$E$3:$E$107="China")*('Assessment Matrix'!$F$3:$F$107="L"))*1)/(SUMPRODUCT(('Assessment Matrix'!$A$3:$A$107="Aviation")*('Assessment Matrix'!$E$3:$E$107="China")*(('Assessment Matrix'!$F$3:$F$107="H")+('Assessment Matrix'!$F$3:$F$107="M")+('Assessment Matrix'!$F$3:$F$107="L")))),"") -> 1
B12: Shipping | C12: =IFERROR((SUMPRODUCT(('Assessment Matrix'!$A$3:$A$107="Shipping")*('Assessment Matrix'!$E$3:$E$107="European Union")*('Assessment Matrix'!$F$3:$F$107="H"))*3+SUMPRODUCT(('Assessment Matrix'!$A$3:$A$107="Shipping")*('Assessment Matrix'!$E$3:$E$107="European Union")*('Assessment Matrix'!$F$3:$F$107="M"))*2+SUMPRODUCT(('Assessment Matrix'!$A$3:$A$107="Shipping")*('Assessment Matrix'!$E$3:$E$107="European Union")*('Assessment Matrix'!$F$3:$F$107="L"))*1)/(SUMPRODUCT(('Assessment Matrix'!$A$3:$A$107="Shipping")*('Assessment Matrix'!$E$3:$E$107="European Union")*(('Assessment Matrix'!$F$3:$F$107="H")+('Assessment Matrix'!$F$3:$F$107="M")+('Assessment Matrix'!$F$3:$F$107="L")))),"") -> 2.3333333 | D12: =IFERROR((SUMPRODUCT(('Assessment Matrix'!$A$3:$A$107="Shipping")*('Assessment Matrix'!$E$3:$E$107="United States")*('Assessment Matrix'!$F$3:$F$107="H"))*3+SUMPRODUCT(('Assessment Matrix'!$A$3:$A$107="Shipping")*('Assessment Matrix'!$E$3:$E$107="United States")*('Assessment Matrix'!$F$3:$F$107="M"))*2+SUMPRODUCT(('Assessment Matrix'!$A$3:$A$107="Shipping")*('Assessment Matrix'!$E$3:$E$107="United States")*('Assessment Matrix'!$F$3:$F$107="L"))*1)/(SUMPRODUCT(('Assessment Matrix'!$A$3:$A$107="Shipping")*('Assessment Matrix'!$E$3:$E$107="United States")*(('Assessment Matrix'!$F$3:$F$107="H")+('Assessment Matrix'!$F$3:$F$107="M")+('Assessment Matrix'!$F$3:$F$107="L")))),"") -> 1.3333333 | E12: =IFERROR((SUMPRODUCT(('Assessment Matrix'!$A$3:$A$107="Shipping")*('Assessment Matrix'!$E$3:$E$107="China")*('Assessment Matrix'!$F$3:$F$107="H"))*3+SUMPRODUCT(('Assessment Matrix'!$A$3:$A$107="Shipping")*('Assessment Matrix'!$E$3:$E$107="China")*('Assessment Matrix'!$F$3:$F$107="M"))*2+SUMPRODUCT(('Assessment Matrix'!$A$3:$A$107="Shipping")*('Assessment Matrix'!$E$3:$E$107="China")*('Assessment Matrix'!$F$3:$F$107="L"))*1)/(SUMPRODUCT(('Assessment Matrix'!$A$3:$A$107="Shipping")*('Assessment Matrix'!$E$3:$E$107="China")*(('Assessment Matrix'!$F$3:$F$107="H")+('Assessment Matrix'!$F$3:$F$107="M")+('Assessment Matrix'!$F$3:$F$107="L")))),"") -> 1.6666667
B13: Heavy-Duty Road Transport | C13: =IFERROR((SUMPRODUCT(('Assessment Matrix'!$A$3:$A$107="Heavy-Duty Road Transport")*('Assessment Matrix'!$E$3:$E$107="European Union")*('Assessment Matrix'!$F$3:$F$107="H"))*3+SUMPRODUCT(('Assessment Matrix'!$A$3:$A$107="Heavy-Duty Road Transport")*('Assessment Matrix'!$E$3:$E$107="European Union")*('Assessment Matrix'!$F$3:$F$107="M"))*2+SUMPRODUCT(('Assessment Matrix'!$A$3:$A$107="Heavy-Duty Road Transport")*('Assessment Matrix'!$E$3:$E$107="European Union")*('Assessment Matrix'!$F$3:$F$107="L"))*1)/(SUMPRODUCT(('Assessment Matrix'!$A$3:$A$107="Heavy-Duty Road Transport")*('Assessment Matrix'!$E$3:$E$107="European Union")*(('Assessment Matrix'!$F$3:$F$107="H")+('Assessment Matrix'!$F$3:$F$107="M")+('Assessment Matrix'!$F$3:$F$107="L")))),"") -> 2.3333333 | D13: =IFERROR((SUMPRODUCT(('Assessment Matrix'!$A$3:$A$107="Heavy-Duty Road Transport")*('Assessment Matrix'!$E$3:$E$107="United States")*('Assessment Matrix'!$F$3:$F$107="H"))*3+SUMPRODUCT(('Assessment Matrix'!$A$3:$A$107="Heavy-Duty Road Transport")*('Assessment Matrix'!$E$3:$E$107="United States")*('Assessment Matrix'!$F$3:$F$107="M"))*2+SUMPRODUCT(('Assessment Matrix'!$A$3:$A$107="Heavy-Duty Road Transport")*('Assessment Matrix'!$E$3:$E$107="United States")*('Assessment Matrix'!$F$3:$F$107="L"))*1)/(SUMPRODUCT(('Assessment Matrix'!$A$3:$A$107="Heavy-Duty Road Transport")*('Assessment Matrix'!$E$3:$E$107="United States")*(('Assessment Matrix'!$F$3:$F$107="H")+('Assessment Matrix'!$F$3:$F$107="M")+('Assessment Matrix'!$F$3:$F$107="L")))),"") -> 1.6666667 | E13: =IFERROR((SUMPRODUCT(('Assessment Matrix'!$A$3:$A$107="Heavy-Duty Road Transport")*('Assessment Matrix'!$E$3:$E$107="China")*('Assessment Matrix'!$F$3:$F$107="H"))*3+SUMPRODUCT(('Assessment Matrix'!$A$3:$A$107="Heavy-Duty Road Transport")*('Assessment Matrix'!$E$3:$E$107="China")*('Assessment Matrix'!$F$3:$F$107="M"))*2+SUMPRODUCT(('Assessment Matrix'!$A$3:$A$107="Heavy-Duty Road Transport")*('Assessment Matrix'!$E$3:$E$107="China")*('Assessment Matrix'!$F$3:$F$107="L"))*1)/(SUMPRODUCT(('Assessment Matrix'!$A$3:$A$107="Heavy-Duty Road Transport")*('Assessment Matrix'!$E$3:$E$107="China")*(('Assessment Matrix'!$F$3:$F$107="H")+('Assessment Matrix'!$F$3:$F$107="M")+('Assessment Matrix'!$F$3:$F$107="L")))),"") -> 2.3333333
B14: Oil & Gas Upstream | C14: =IFERROR((SUMPRODUCT(('Assessment Matrix'!$A$3:$A$107="Oil & Gas Upstream")*('Assessment Matrix'!$E$3:$E$107="European Union")*('Assessment Matrix'!$F$3:$F$107="H"))*3+SUMPRODUCT(('Assessment Matrix'!$A$3:$A$107="Oil & Gas Upstream")*('Assessment Matrix'!$E$3:$E$107="European Union")*('Assessment Matrix'!$F$3:$F$107="M"))*2+SUMPRODUCT(('Assessment Matrix'!$A$3:$A$107="Oil & Gas Upstream")*('Assessment Matrix'!$E$3:$E$107="European Union")*('Assessment Matrix'!$F$3:$F$107="L"))*1)/(SUMPRODUCT(('Assessment Matrix'!$A$3:$A$107="Oil & Gas Upstream")*('Assessment Matrix'!$E$3:$E$107="European Union")*(('Assessment Matrix'!$F$3:$F$107="H")+('Assessment Matrix'!$F$3:$F$107="M")+('Assessment Matrix'!$F$3:$F$107="L")))),"") -> 2.3333333 | D14: =IFERROR((SUMPRODUCT(('Assessment Matrix'!$A$3:$A$107="Oil & Gas Upstream")*('Assessment Matrix'!$E$3:$E$107="United States")*('Assessment Matrix'!$F$3:$F$107="H"))*3+SUMPRODUCT(('Assessment Matrix'!$A$3:$A$107="Oil & Gas Upstream")*('Assessment Matrix'!$E$3:$E$107="United States")*('Assessment Matrix'!$F$3:$F$107="M"))*2+SUMPRODUCT(('Assessment Matrix'!$A$3:$A$107="Oil & Gas Upstream")*('Assessment Matrix'!$E$3:$E$107="United States")*('Assessment Matrix'!$F$3:$F$107="L"))*1)/(SUMPRODUCT(('Assessment Matrix'!$A$3:$A$107="Oil & Gas Upstream")*('Assessment Matrix'!$E$3:$E$107="United States")*(('Assessment Matrix'!$F$3:$F$107="H")+('Assessment Matrix'!$F$3:$F$107="M")+('Assessment Matrix'!$F$3:$F$107="L")))),"") -> 1.6666667 | E14: =IFERROR((SUMPRODUCT(('Assessment Matrix'!$A$3:$A$107="Oil & Gas Upstream")*('Assessment Matrix'!$E$3:$E$107="China")*('Assessment Matrix'!$F$3:$F$107="H"))*3+SUMPRODUCT(('Assessment Matrix'!$A$3:$A$107="Oil & Gas Upstream")*('Assessment Matrix'!$E$3:$E$107="China")*('Assessment Matrix'!$F$3:$F$107="M"))*2+SUMPRODUCT(('Assessment Matrix'!$A$3:$A$107="Oil & Gas Upstream")*('Assessment Matrix'!$E$3:$E$107="China")*('Assessment Matrix'!$F$3:$F$107="L"))*1)/(SUMPRODUCT(('Assessment Matrix'!$A$3:$A$107="Oil & Gas Upstream")*('Assessment Matrix'!$E$3:$E$107="China")*(('Assessment Matrix'!$F$3:$F$107="H")+('Assessment Matrix'!$F$3:$F$107="M")+('Assessment Matrix'!$F$3:$F$107="L")))),"") -> 1.3333333
B16: Scores: 3.0 = fully High, 2.0 = fully Moderate, 1.0 = fully Low. Computed live via SUMPRODUCT from the Assessment Matrix sheet.
B17: Legend: ●●● 2.5-3.0 High feasibility ●●○ 1.5-2.49 Moderate ●○○ 1.0-1.49 Low

Sheet Power & Utilities
B2: Power & Utilities
B3: ~40% of global energy-related CO2 (IEA, power generation)
B4: Dominant emission source: Fossil fuel combustion (coal, gas) for electricity generation
B6: Category | C6: Code | D6: Criterion | E6: Region | F6: Rating | G6: Confidence | H6: Evidence | I6: Source
B7: Technology | C7: PWR-T1 | D7: Levelised cost of renewable generation vs. new-build fossil | E7: European Union | F7: H | G7: high | H7: EU utility-scale solar and onshore wind LCOE (~EUR 40-60/MWh in strong-resource markets) is at or below new-build CCGT LCOE; renewables have won the large majority of new capacity tenders since 2022 | I7: IEA World Energy Investment 2023; IRENA Renewable Power Generation Costs 2023
B8: Technology | C8: PWR-T1 | D8: Levelised cost of renewable generation vs. new-build fossil | E8: United States | F8: H | G8: high | H8: Unsubsidized utility-scale solar and wind LCOE in Lazard's most recent analysis sits below new-build gas CCGT in most regions; IRA production tax credits further widen the gap | I8: Lazard Levelized Cost of Energy Analysis; IEA World Energy Investment 2023
B9: Technology | C9: PWR-T1 | D9: Levelised cost of renewable generation vs. new-build fossil | E9: China | F9: H | G9: medium | H9: China's solar and wind LCOE benefits from the world's largest manufacturing scale; renewables are cost-competitive with new coal in the large majority of provinces | I9: IEA World Energy Investment 2023; IRENA Renewable Power Generation Costs 2023
B10: Technology | C10: PWR-T2 | D10: Grid-scale storage / firming technology readiness | E10: European Union | F10: M | G10: medium | H10: Grid-scale battery deployment growing rapidly but curtailment already material in high-renewable-penetration markets (e.g. Germany, Spain, Italy) pending grid reinforcement | I10: IEA Energy Storage tracking report; ENTSO-E curtailment statistics
B11: Technology | C11: PWR-T2 | D11: Grid-scale storage / firming technology readiness | E11: United States | F11: M | G11: medium | H11: Battery storage additions record-high but concentrated in a few states (California, Texas); interconnection queue backlogs remain a binding constraint nationally | I11: IEA Energy Storage tracking report; BloombergNEF Energy Storage Outlook
B12: Technology | C12: PWR-T2 | D12: Grid-scale storage / firming technology readiness | E12: China | F12: M | G12: medium | H12: China leads global battery storage manufacturing and deployment volume, but curtailment of wind/solar in resource-rich western provinces remains a persistent grid integration issue | I12: IEA Energy Storage tracking report
B13: Regulation | C13: PWR-R1 | D13: Effective carbon price on power generation | E13: European Union | F13: H | G13: high | H13: EU ETS price has traded consistently in the EUR 60-90/tCO2 range through 2024-2026, exceeding the H threshold | I13: EEX EUA spot price series; European Commission EU ETS reporting
B14: Regulation | C14: PWR-R1 | D14: Effective carbon price on power generation | E14: United States | F14: M | G14: high | H14: No federal carbon price; state-level programmes (California cap-and-trade, RGGI) apply a moderate price only in participating states, well below the EU level | I14: World Bank Carbon Pricing Dashboard
B15: Regulation | C15: PWR-R1 | D15: Effective carbon price on power generation | E15: China | F15: M | G15: high | H15: China national ETS covers power generation with a 2024 composite closing price ranging CNY 69-106/tonne (year-end CNY 97.49/t, approx. USD 13-14/t), rising further to CNY 66.9-97/t through the 2025 sectoral expansion period — consistently below the USD 60/tCO2 H threshold and well below the EU ETS level (EUR 70-90/t). | I15: Progress Report of China's National Carbon Market (2025), Ministry of Ecology and Environment via Henan provincial exchange; ICAP China National ETS tracker
B16: Regulation | C16: PWR-R2 | D16: Renewable deployment target and permitting regime | E16: European Union | F16: H | G16: high | H16: Binding 2030 renewables target under the revised Renewable Energy Directive, combined with permitting reform under REPowerEU aimed at reducing approval timelines | I16: European Commission REPowerEU / Renewable Energy Directive (EU) 2023/2413
B17: Regulation | C17: PWR-R2 | D17: Renewable deployment target and permitting regime | E17: United States | F17: M | G17: high | H17: No binding federal renewable target; state-level RPS programmes vary widely; interconnection queue times remain a widely documented bottleneck exceeding 3 years in most regions | I17: IEA Renewables market report; Lawrence Berkeley National Laboratory interconnection queue studies
... B21: Demand & Economics | C21: PWR-D1 | D21: Corporate and utility PPA market depth | E21: China | F21: M | G21: low | H21: Corporate PPA market exists and is growing but remains smaller and less standardised than the US/EU, with continued dominance of state-directed offtake structures | I21: BloombergNEF Corporate Energy Market Outlook; directional estimate pending primary verification

Sheet Steel
B2: Steel
B3: ~7-9% of global CO2 emissions (World Steel Association / IEA)
B4: Dominant emission source: Coal used as chemical reductant in blast furnace-basic oxygen furnace (BF-BOF) route
B6: Category | C6: Code | D6: Criterion | E6: Region | F6: Rating | G6: Confidence | H6: Evidence | I6: Source
B7: Technology | C7: STL-T1 | D7: Green hydrogen cost vs. DRI-H2 breakeven | E7: European Union | F7: M | G7: medium | H7: Nordic green hydrogen costs (Sweden, aided by cheap hydro/wind power and long-term renewable power contracts) are approaching but not yet at the cited DRI-H2 breakeven range; wider EU average remains further from breakeven | I7: IEA Global Hydrogen Review; Mission Possible Partnership Steel Transition Strategy
B8: Technology | C8: STL-T1 | D8: Green hydrogen cost vs. DRI-H2 breakeven | E8: United States | F8: M | G8: high | H8: IRA Section 45V hydrogen production tax credit materially improves US green hydrogen economics in optimal wind/solar locations, but the credit's availability window has been shortened: the One Big Beautiful Bill Act (July 2025) accelerated termination to projects that have not begun construction by 1 January 2028 — five years earlier than the original IRA sunset. Delivered green hydrogen cost to steel plants remains above DRI-H2 breakeven in most US regions absent the credit, and the credit's shortened runway increases execution timeline risk for projects not already under construction. | I8: US Treasury/IRS Section 45V final regulations (3 Jan 2025); Sidley Austin, Velaw, Baker Botts, Pillsbury legislative summaries of OBBBA Section 45V provisions
B9: Technology | C9: STL-T1 | D9: Green hydrogen cost vs. DRI-H2 breakeven | E9: China | F9: L | G9: low | H9: Chinese green hydrogen costs remain above Nordic and optimal-US levels due to less mature electrolyser supply chain economics for green (as opposed to grey/coal-based) hydrogen at scale | I9: IEA Global Hydrogen Review; directional estimate pending primary verification
B10: Technology | C10: STL-T2 | D10: Scrap steel availability (EAF route feasibility) | E10: European Union | F10: M | G10: medium | H10: EU scrap collection and recycling rates are relatively mature but crude steel production still runs materially above the scrap-availability threshold for full EAF conversion | I10: World Steel Association Steel Statistical Yearbook
B11: Technology | C11: STL-T2 | D11: Scrap steel availability (EAF route feasibility) | E11: United States | F11: H | G11: high | H11: US steel industry already has one of the highest EAF shares globally (~70% of production), reflecting high domestic scrap availability | I11: World Steel Association Steel Statistical Yearbook; American Iron and Steel Institute
B12: Technology | C12: STL-T2 | D12: Scrap steel availability (EAF route feasibility) | E12: China | F12: L | G12: medium | H12: China's steel fleet is dominated by BF-BOF production with an EAF share well below the global average; scrap availability constrained by the relative youth of the domestic steel stock | I12: World Steel Association Steel Statistical Yearbook; OECD Steel Market Developments
B13: Regulation | C13: STL-R1 | D13: Effective carbon price on steel production incl. border adjustment | E13: European Union | F13: H | G13: high | H13: EU ETS price in the effective range plus CBAM definitive-regime entry from 2026, phasing out free allocation for steel in parallel, creates the H-level combination of price and border protection | I13: EU CBAM Regulation 2023/956; European Commission DG CLIMA free allocation benchmarks
B14: Regulation | C14: STL-R1 | D14: Effective carbon price on steel production incl. border adjustment | E14: United States | F14: L | G14: high | H14: No federal carbon price applies to steel production and no equivalent border adjustment mechanism is in force | I14: World Bank Carbon Pricing Dashboard
B15: Regulation | C15: STL-R1 | D15: Effective carbon price on steel production incl. border adjustment | E15: China | F15: L | G15: high | H15: China's national ETS was expanded in 2025 to formally include the steel sector (alongside cement and aluminium smelting), raising national coverage from ~40% to ~60%+ of emissions. However, the post-expansion carbon price (CNY 66.9-97/tonne through late 2024-2025, approx. USD 9-14/tonne) remains far below the level needed to close the green steel cost gap: analysis shows a carbon price of approximately CNY 890/tonne (~USD 124/t) would be needed for DRI-H2 cost parity at current green hydrogen prices — roughly 9x the current price and 1.6x the EU ETS level. First compliance deadline for the newly covered sectors is end-2025, covering 2024 emissions, with free allocation dominating in the initial 2024-2026 period. | I15: Ministry of Ecology and Environment (China) allocation plan (Nov 2025); ICAP China National ETS tracker; IEEFA ETS reforms analysis; Transition Asia sector brief (Sept 2025) for the 890 yuan/t breakeven calculation
B16: Regulation | C16: STL-R2 | D16: Green/low-carbon steel public procurement or building-code mandate | E16: European Union | F16: M | G16: medium | H16: EU Green Public Procurement criteria exist and several member states have piloted embodied-carbon requirements in public construction, but a binding EU-wide mandate for steel specifically is not yet in force | I16: European Commission DG ENV Green Public Procurement criteria
B17: Regulation | C17: STL-R2 | D17: Green/low-carbon steel public procurement or building-code mandate | E17: United States | F17: M | G17: medium | H17: Federal Buy Clean Initiative directs federal procurement toward lower-embodied-carbon materials including steel, but scope is limited to federal contracts rather than an economy-wide mandate | I17: US GSA / EPA Federal Buy Clean Initiative
... B21: Demand & Economics | C21: STL-D1 | D21: Green steel price premium and recoverability | E21: China | F21: L | G21: medium | H21: No material domestic green steel premium or offtake market identified; CBAM exposure affects only the exported share of Chinese steel production | I21: BloombergNEF Green Steel Tracker

Sheet Cement
B2: Cement
B3: ~7% of global CO2 emissions (IEA / Global Cement and Concrete Association)
B4: Dominant emission source: Limestone calcination (process emissions, ~60%) plus kiln fuel combustion
B6: Category | C6: Code | D6: Criterion | E6: Region | F6: Rating | G6: Confidence | H6: Evidence | I6: Source
B7: Technology | C7: CEM-T1 | D7: CCS capture technology deployment status | E7: European Union | F7: H | G7: high | H7: A full-scale cement CCS facility in Norway is operational (~0.4 Mtpa), the first of its kind globally, establishing an operating track record | I7: Global CCS Institute CO2RE database; company project disclosures
B8: Technology | C8: CEM-T1 | D8: CCS capture technology deployment status | E8: United States | F8: M | G8: medium | H8: Several cement CCS projects are in planning or FID stage under DOE Industrial Demonstrations Program support, but no full-scale facility is yet operational | I8: Global CCS Institute CO2RE database; US DOE Industrial Demonstrations Program
B9: Technology | C9: CEM-T1 | D9: CCS capture technology deployment status | E9: China | F9: L | G9: low | H9: No full-scale operational or FID-stage cement CCS facility identified in China as of the assessment date | I9: Global CCS Institute CO2RE database; pending direct verification
B10: Technology | C10: CEM-T2 | D10: Clinker substitution rate (SCM availability) | E10: European Union | F10: M | G10: medium | H10: EU average clinker ratio has been declining via SCM substitution but remains above the H threshold on a region-wide basis | I10: Global Cement and Concrete Association sustainability data
B11: Technology | C11: CEM-T2 | D11: Clinker substitution rate (SCM availability) | E11: United States | F11: M | G11: medium | H11: US clinker ratio broadly similar to EU average; fly ash availability declining as coal plants retire, creating a supply constraint on this specific SCM | I11: Global Cement and Concrete Association sustainability data; Portland Cement Association
B12: Technology | C12: CEM-T2 | D12: Clinker substitution rate (SCM availability) | E12: China | F12: M | G12: low | H12: China's large cement sector has significant SCM substitution in some provinces, but sector-wide average clinker ratio data is less transparently reported than in the EU/US | I12: Global Cement and Concrete Association; directional estimate pending primary verification
B13: Regulation | C13: CEM-R1 | D13: Effective carbon price on cement production incl. border adjustment | E13: European Union | F13: H | G13: high | H13: EU ETS price plus CBAM coverage of cement from the definitive regime, with free allocation phasing out in parallel | I13: EU CBAM Regulation 2023/956; European Commission DG CLIMA cement clinker benchmark
B14: Regulation | C14: CEM-R1 | D14: Effective carbon price on cement production incl. border adjustment | E14: United States | F14: L | G14: high | H14: No federal carbon price applies to cement production and no border adjustment mechanism is in force | I14: World Bank Carbon Pricing Dashboard
